Workbook

Sheet All Disasters
A1: Disaster Row # | B1: Name | C1: Disaster Type | D1: Begin Date | E1: End Date | F1: CPI-Adjusted Cost ($M) | G1: Unadjusted Cost ($M) | H1: Deaths | I1: States | J1: Engines | K1: # Articles Found | L1: Avg Attribution Index | M1: Contested Share
A2: 1 | B2: Southeast Winter Storm (January 2000) | C2: Winter Storm | D2: 20000121 | E2: 20000124 | F2: 1320.3 | G2: 706 | H2: 4 | I2: AL,FL,GA,KY,MS,NC,SC,TN,VA,WV | J2: 3,4,5,6,7,8,National | K2: =COUNTIF(Master!A$2:A$2428,A2) | L2: =IFERROR(AVERAGEIFS(Master!P$2:P$2428,Master!A$2:A$2428,A2,Master!O$2:O$2428,"Relevant"),"") | M2: =IFERROR(COUNTIFS(Master!A$2:A$2428,A2,Master!O$2:O$2428,"Relevant",Master!S$2:S$2428,TRUE)/COUNTIFS(Master!A$2:A$2428,A2,Master!O$2:O$2428,"Relevant"),"")
A3: 2 | B3: Southern Severe Weather (March 2000) | C3: Severe Storm | D3: 20000328 | E3: 20000329 | F3: 1269.6 | G3: 690 | H3: 0 | I3: AL,AR,FL,GA,KY,LA,MS,NC,OK,SC,TN,TX,VA | J3: 13,14,15,3,4,5,6,7,8,National | K3: =COUNTIF(Master!A$2:A$2428,A3) | L3: =IFERROR(AVERAGEIFS(Master!P$2:P$2428,Master!A$2:A$2428,A3,Master!O$2:O$2428,"Relevant"),"") | M3: =IFERROR(COUNTIFS(Master!A$2:A$2428,A3,Master!O$2:O$2428,"Relevant",Master!S$2:S$2428,TRUE)/COUNTIFS(Master!A$2:A$2428,A3,Master!O$2:O$2428,"Relevant"),"")
A4: 3 | B4: Western Fire Season (Spring-Summer 2000) | C4: Wildfire | D4: 20000301 | E4: 20000831 | F4: 1978 | G4: 1075 | H4: 0 | I4: AK,AZ,CA,CO,HI,ID,MT,NM,NV,OR,UT,WA,WY | J4: 15,16,17,18,National | K4: =COUNTIF(Master!A$2:A$2428,A4) | L4: =IFERROR(AVERAGEIFS(Master!P$2:P$2428,Master!A$2:A$2428,A4,Master!O$2:O$2428,"Relevant"),"") | M4: =IFERROR(COUNTIFS(Master!A$2:A$2428,A4,Master!O$2:O$2428,"Relevant",Master!S$2:S$2428,TRUE)/COUNTIFS(Master!A$2:A$2428,A4,Master!O$2:O$2428,"Relevant"),"")
A5: 4 | B5: South Florida Flooding (October 2000) | C5: Flooding | D5: 20001003 | E5: 20001004 | F5: 1629 | G5: 900 | H5: 3 | I5: FL | J5: 3,4,5,6,National | K5: =COUNTIF(Master!A$2:A$2428,A5) | L5: =IFERROR(AVERAGEIFS(Master!P$2:P$2428,Master!A$2:A$2428,A5,Master!O$2:O$2428,"Relevant"),"") | M5: =IFERROR(COUNTIFS(Master!A$2:A$2428,A5,Master!O$2:O$2428,"Relevant",Master!S$2:S$2428,TRUE)/COUNTIFS(Master!A$2:A$2428,A5,Master!O$2:O$2428,"Relevant"),"")
A6: 5 | B6: Western/Central/Southeast Drought/Heat Wave (Spring-Fall 2000) | C6: Drought | D6: 20000301 | E6: 20001130 | F6: 9344.8 | G6: 4997.2 | H6: 140 | I6: AK,AL,AZ,CA,CO,FL,GA,HI,IA,ID,IL,IN,KS,KY,MI,MN,MO,MS,MT,NC,ND,NE,NM,NV,OH,OK,OR,SC,SD,TN,TX,UT,VA,WA,WI,WV,WY | J6: 10,11,12,13,14,15,16,17,18,3,4,5,6,7,8,9,National | K6: =COUNTIF(Master!A$2:A$2428,A6) | L6: =IFERROR(AVERAGEIFS(Master!P$2:P$2428,Master!A$2:A$2428,A6,Master!O$2:O$2428,"Relevant"),"") | M6: =IFERROR(COUNTIFS(Master!A$2:A$2428,A6,Master!O$2:O$2428,"Relevant",Master!S$2:S$2428,TRUE)/COUNTIFS(Master!A$2:A$2428,A6,Master!O$2:O$2428,"Relevant"),"")
A7: 6 | B7: Midwest/Ohio Valley Hail and Tornadoes (April 2001) | C7: Severe Storm | D7: 20010406 | E7: 20010411 | F7: 5508.7 | G7: 3094.8 | H7: 3 | I7: IA,IL,IN,KS,KY,MI,MN,MO,ND,NE,OH,SD,TN,WI,WV | J7: 10,11,12,13,3,4,5,6,7,8,9,National | K7: =COUNTIF(Master!A$2:A$2428,A7) | L7: =IFERROR(AVERAGEIFS(Master!P$2:P$2428,Master!A$2:A$2428,A7,Master!O$2:O$2428,"Relevant"),"") | M7: =IFERROR(COUNTIFS(Master!A$2:A$2428,A7,Master!O$2:O$2428,"Relevant",Master!S$2:S$2428,TRUE)/COUNTIFS(Master!A$2:A$2428,A7,Master!O$2:O$2428,"Relevant"),"")
A8: 7 | B8: North Central Severe Weather (May 2001) | C8: Severe Storm | D8: 20010430 | E8: 20010501 | F8: 1194.3 | G8: 671 | H8: 0 | I8: IA,IL,IN,KS,MI,MN,MO,ND,NE,OH,SD,WI | J8: 10,11,12,13,8,9,National | K8: =COUNTIF(Master!A$2:A$2428,A8) | L8: =IFERROR(AVERAGEIFS(Master!P$2:P$2428,Master!A$2:A$2428,A8,Master!O$2:O$2428,"Relevant"),"") | M8: =IFERROR(COUNTIFS(Master!A$2:A$2428,A8,Master!O$2:O$2428,"Relevant",Master!S$2:S$2428,TRUE)/COUNTIFS(Master!A$2:A$2428,A8,Master!O$2:O$2428,"Relevant"),"")
A9: 8 | B9: Tropical Storm Allison (June 2001) | C9: Tropical Cyclone | D9: 20010605 | E9: 20010617 | F9: 15084 | G9: 8522 | H9: 43 | I9: LA,TX | J9: 13,14,15,National | K9: =COUNTIF(Master!A$2:A$2428,A9) | L9: =IFERROR(AVERAGEIFS(Master!P$2:P$2428,Master!A$2:A$2428,A9,Master!O$2:O$2428,"Relevant"),"") | M9: =IFERROR(COUNTIFS(Master!A$2:A$2428,A9,Master!O$2:O$2428,"Relevant",Master!S$2:S$2428,TRUE)/COUNTIFS(Master!A$2:A$2428,A9,Master!O$2:O$2428,"Relevant"),"")
A10: 9 | B10: Severe Storms and Tornadoes (April 2002) | C10: Severe Storm | D10: 20020427 | E10: 20020428 | F10: 3663.9 | G10: 2093.8 | H10: 7 | I10: NATIONAL | J10: National | K10: =COUNTIF(Master!A$2:A$2428,A10) | L10: =IFERROR(AVERAGEIFS(Master!P$2:P$2428,Master!A$2:A$2428,A10,Master!O$2:O$2428,"Relevant"),"") | M10: =IFERROR(COUNTIFS(Master!A$2:A$2428,A10,Master!O$2:O$2428,"Relevant",Master!S$2:S$2428,TRUE)/COUNTIFS(Master!A$2:A$2428,A10,Master!O$2:O$2428,"Relevant"),"")
A11: 10 | B11: Hurricane Lili (October 2002) | C11: Tropical Cyclone | D11: 20020801 | E11: 20020805 | F11: 1932.9 | G11: 1104.5 | H11: 2 | I11: LA | J11: 13,14,15,National | K11: =COUNTIF(Master!A$2:A$2428,A11) | L11: =IFERROR(AVERAGEIFS(Master!P$2:P$2428,Master!A$2:A$2428,A11,Master!O$2:O$2428,"Relevant"),"") | M11: =IFERROR(COUNTIFS(Master!A$2:A$2428,A11,Master!O$2:O$2428,"Relevant",Master!S$2:S$2428,TRUE)/COUNTIFS(Master!A$2:A$2428,A11,Master!O$2:O$2428,"Relevant"),"")
A12: 11 | B12: Tropical Storm Isidore (September 2002) | C12: Tropical Cyclone | D12: 20020925 | E12: 20020927 | F12: 2001 | G12: 1150 | H12: 5 | I12: AL,LA,MS | J12: 13,14,15,6,7,8,National | K12: =COUNTIF(Master!A$2:A$2428,A12) | L12: =IFERROR(AVERAGEIFS(Master!P$2:P$2428,Master!A$2:A$2428,A12,Master!O$2:O$2428,"Relevant"),"") | M12: =IFERROR(COUNTIFS(Master!A$2:A$2428,A12,Master!O$2:O$2428,"Relevant",Master!S$2:S$2428,TRUE)/COUNTIFS(Master!A$2:A$2428,A12,Master!O$2:O$2428,"Relevant"),"")
A13: 12 | B13: Eastern Tornadoes and Severe Storms (November 2002) | C13: Severe Storm | D13: 20021109 | E13: 20021111 | F13: 1252.8 | G13: 720 | H13: 28 | I13: CT,DE,FL,GA,MA,MD,ME,NC,NH,NJ,NY,PA,RI,SC,VA,VT,WV | J13: 1,2,3,4,5,6,National | K13: =COUNTIF(Master!A$2:A$2428,A13) | L13: =IFERROR(AVERAGEIFS(Master!P$2:P$2428,Master!A$2:A$2428,A13,Master!O$2:O$2428,"Relevant"),"") | M13: =IFERROR(COUNTIFS(Master!A$2:A$2428,A13,Master!O$2:O$2428,"Relevant",Master!S$2:S$2428,TRUE)/COUNTIFS(Master!A$2:A$2428,A13,Master!O$2:O$2428,"Relevant"),"")
... A314: 313 | B314: Southern/Eastern/Northwestern Drought and Heat Wave (2024) | C314: Drought | D314: 20240101 | E314: 20241231 | F314: 5417 | G314: 5311 | H314: 136 | I314: AL,AR,CT,DE,FL,GA,ID,KY,LA,MA,MD,ME,MS,MT,NC,NH,NJ,NY,OK,OR,PA,RI,SC,TN,TX,VA,VT,WA,WV | J314: 1,13,14,15,16,17,18,2,3,4,5,6,7,8,National | K314: =COUNTIF(Master!A$2:A$2428,A314) | L314: =IFERROR(AVERAGEIFS(Master!P$2:P$2428,Master!A$2:A$2428,A314,Master!O$2:O$2428,"Relevant"),"") | M314: =IFERROR(COUNTIFS(Master!A$2:A$2428,A314,Master!O$2:O$2428,"Relevant",Master!S$2:S$2428,TRUE)/COUNTIFS(Master!A$2:A$2428,A314,Master!O$2:O$2428,"Relevant"),"")

Sheet Master
A1: Disaster Row # | B1: Article # | C1: Name | D1: Disaster Type | E1: Begin Date | F1: End Date | G1: CPI-Adjusted Cost ($M) | H1: Unadjusted Cost ($M) | I1: Deaths | J1: States | K1: Engines | L1: URL | M1: Title | N1: Snippet | O1: Relevance | P1: Attribution Score | Q1: Attribution Category | R1: D-Subtype | S1: Contested | T1: LLM Rationale | U1: National Newspaper | V1: Calibration Sample | W1: Full Article Text | X1: Archive URL | Y1: Archive Status | Z1: Word Count | AA1: Domain | AB1: Ad Fontes Bias Score | AC1: AllSides Rating (Numeric) | AD1: Political Lean Group
A2: 1 | B2: 1 | C2: Southeast Winter Storm (January 2000) | D2: Winter Storm | E2: 20000121 | F2: 20000124 | G2: 1320.3 | H2: 706 | I2: 4 | J2: AL,FL,GA,KY,MS,NC,SC,TN,VA,WV | K2: 3,4,5,6,7,8,National | L2: https://www.nytimes.com/2000/01/24/us/500000-homes-left-dark-by-ice-storm-in-southeast.html | M2: 500000 Homes Left Dark By Ice Storm in Southeast | N2: Jan 24, 2000 ... Winter storm sweeps Southeast, from northeast Georgia to central ... 24, 2000, Section A, Page 12 of the National edition with the ... | O2: Relevant | P2: 0 | Q2: C | S2: FALSE | T2: Backfilled from Calibration sheet's LLM code -- this article was part of the 50-article human/LLM calibration sample and was intentionally skipped by the full-sample coding pass to avoid double-coding/double-cost. See Calibration sheet for the original human vs. LLM comparison and reliability stats. | U2: =IF(SUMPRODUCT(--ISNUMBER(SEARCH('National Domains'!$A$2:$A$48,L2)))>0,"Yes","No") | V2: =IF(COUNTIFS(Calibration!$A:$A,A2,Calibration!$B:$B,B2)>0,"Yes","No") | W2: ATLANTA, Jan. 23 -- A sluggish winter storm dripped a crippling coating of ice on much of the Southeast today, cracking thousands of drooping pine trees and cutting off electric power to more than 500,000 households, mostly in Atlanta. From northeast Georgia to central North Carolina, hundreds of roads were closed by fallen pines, never the sturdiest trees even in normal conditions. In urban areas, the trees generally took power lines down with them, leaving many neighborhoods in Atlanta a chaotic mix of scattered tree limbs, live wires and nonfunctioning traffic lights. ''In 18 years, this is the most ice I've ever seen accumulate,'' said Tom Moore, senior meteorologist with the Weather Channel, which is based here. ''The saving grace was that it was a Sunday morning.'' Many other Atlantans were also thankful the storm did not occur a week later, when the Super Bowl will be played at the Georgia Dome downtown. About 320,000 homes in Atlanta -- a quarter of the metropolitan area --were without power by this evening, said Lisa Frederick, a spokeswoman for Georgia Power. Atlanta is one of the most heavily forested cities in the country, and because of the large number of fallen trees, the company said it might be two days before power is restored. In some cases, lights that came back on went off again an hour later when another tree succumbed. It was the worst storm in the area since crews took a week to restore power to 570,000 customers after a blizzard in March 1993, Ms. Frederick said. Most homes in the region are heated by forced-air furnaces, which require electricity. With temperatures hovering around freezing, many people huddled near fireplaces or relied on kerosene heaters, which sold briskly at stores. Inevitably, the reliance on heaters produced a rash of house fires, the worst of which killed three people on the southwest side of the city early today. Many families lost both their power and their roofs to falling trees. Kent M. Harper arrived at his Dekalb County home this morning after his evening shift at the post office to find two large tree limbs protruding from his roof. ''It was like somebody had thrown a spear or a javelin through it,'' said Mr. Harper, a transportation supervisor, surveying the icicles building up in his living room. ''I knew I should have had those pine trees cut down.'' His family, like many others, cooked lunch in an iron skillet in the fireplace. Chain saws echoed throughout the city as people tried to move limbs covered with a half-inch of ice. Many people in the northern suburbs were trapped in their subdivisions until someone with a saw or a winch could clear an entrance road. Even walking was hazardous, as any branch could fall with a gunfire crack and a shower of ice. ''I heard an explosion, and then I ran,'' said Germaine Dozier, a receptionist who was walking in her midtown neighborhood this morning. ''This huge branch fell right where I was standing. It was like wartime or something.'' The ice coated about 40 counties in the northern third of Georgia, according to the state emergency management agency, and conditions in seven counties were serious enough that the state declared emergencies, urging motorists not to go out. Similar conditions prevailed in parts of southeastern Tennessee and western portions of the Carolinas. Mr. Moore said the ice was the result of a layer of warm air that floated atop a colder layer near the ground. Without the warmth, the rain might have turned to less damaging snow, he said. The storm extended from Alabama, where 33,000 homes and businesses were without power, to around Greensboro, N.C. North Carolina's major utilities reported approximately 20,000 customers without electricity today after parts of that state got a mixture of sleet, rain and snow. But, a Carolina Power and Light spokeswoman, Sally Ramey, said not all of the power losses could be blamed on the weather. Parts of South Carolina got up to 6 inches of snow late Saturday, and traffic on Interstate 85 came to a standstill in several spots because of slippery pavement and accidents. Hartsfield International Airport in Atlanta, the world's busiest, was open through the day, but many flights were delayed for de-icing. In central Tennessee, where 3.5 inches of snow fell on Saturday, a de-icing truck nicked the wing of a Northwest Airlines DC-9 at Nashville International Airport, The Associated Press reported. No one was injured, said a spokeswoman for Northwest, Mary Beth Schubert. -------------------- Jet Slides off Runway CHARLOTTE, N.C., Jan. 23 (AP) -- A US Airways jet skidded off the runway after landing at Charlotte-Douglas International Airport on Saturday as a storm blanketed the area with snow and freezing rain. None of the 142 passengers were hurt. A US Airways spokeswoman, Sharon Taylor, said Flight 2399, an MD-80 coming from Orlando, Fla., landed at 7:26 p.m. and was turning from the runway onto a taxiway when it slid onto a grassy area. ''Everyone was fine,'' Ms. Taylor said. ''We offloaded the passengers on mobile air stairs.'' Most of the passengers made their connecting flights, she said. | X2: http://web.archive.org/web/20251023055611/https://www.nytimes.com/2000/01/24/us/500000-homes-left-dark-by-ice-storm-in-southeast.html | Y2: found | Z2: 858 | AA2: nytimes.com | AB2: -8.02 | AC2: -2.5 | AD2: Left-leaning
A3: 3 | B3: 1 | C3: Western Fire Season (Spring-Summer 2000) | D3: Wildfire | E3: 20000301 | F3: 20000831 | G3: 1978 | H3: 1075 | I3: 0 | J3: AK,AZ,CA,CO,HI,ID,MT,NM,NV,OR,UT,WA,WY | K3: 15,16,17,18,National | L3: http://www.cnn.com/2000/US/08/13/wildfires.02/index.html | M3: Western wildfires finally lose ground - August 13, 2000 - CNN | N3: Aug 13, 2000 ... CNN.com · U.S. News ; Western wildfires finally lose ground. GALLERY. A cheatgrass fire in Nevada moves as fast as the wind will carry it -- ... | O3: Relevant | P3: 0 | Q3: C | S3: FALSE | T3: The article is clearly about the Western wildfire season of summer 2000, covering active fires across multiple affected states, costs, and federal relief efforts. There is no mention of climate change, global warming, or any other causal attribution — it is purely event reporting on fire status, impacts, and response. | U3: =IF(SUMPRODUCT(--ISNUMBER(SEARCH('National Domains'!$A$2:$A$48,L3)))>0,"Yes","No") | V3: =IF(COUNTIFS(Calibration!$A:$A,A3,Calibration!$B:$B,B3)>0,"Yes","No") | W3: HELENA, Montana (CNN) - Firefighters faced a smaller battlefield Sunday as the number of acres ablaze across the West declined slightly. Even so, federal officials have promised to cut through red tape and get immediate financial relief for fire-ravaged Montana -- one of the worst-hit states. On Sunday, the National Fire Information Center reported 76 large fires burning across 868,975 acres -- 54,560 acres less than a day earlier. Although firefighters were contending Sunday with seven additional fires, they took satisfaction in their accomplishment. "We are making progress," said Ed Waldapfel, a spokesman for the National Interagency Fire Center in Boise, Idaho. Wildfires are burning in 13 states: Idaho, Wyoming, Montana, South Dakota, Texas, New Mexico, Arizona, Utah, Nevada, Colorado, Washington, Oregon and California. Residents affected by the fire got a boost Saturday when James Lee Witt, director of the Federal Emergency Management Agency (FEMA), toured burned areas in Montana. He vowed to local and state officials that he would expedite efforts to get federal funds to the state. "They need the money now, and that's what we're going to do," Witt told CNN. To estimate the costs of the ongoing firefighting effort, officials from the emergency management agency will hold a conference call Monday with state officials and those from federal park and forestry agencies, said Matthew Furman, a spokesman for the emergency management agency, during an interview with CNN. Once the estimated cost is determined, Furman said a check will be issued within days for 50 percent of the figure; this will eliminate the need for a special session of the state legislature. In Montana alone, costs on the state, local and federal levels have surpassed $64 million. In the 13 states now battling large fires, the costs are estimated at $15 million per day, noted Waldapfel of the National Interagency Fire Center. "We just need to make sure that we can try to protect homes, and take care of families that have been affected," said Witt. "These people out here have gone through an awful ordeal." Meanwhile, cooler weather in Montana has allowed firefighters to make progress on two fires burning 12 to 15 miles south of Helena. Larry Akers of the Montana Division of Disaster and Emergency Services said a mandatory evacuation order had been lifted covering some 270 residents. Akers noted the evacuations had been ordered eight to 10 days ago. An additional 500 soldiers from the 20th Engineer Battalion, First Cavalry Division at Fort Hood, Texas, have completed their initial training and will begin training on the fire lines Sunday in Montana. South Dakota was added to the list of states battling wildfires. A 1,500 acre fire was burning on the rugged terrain of Flag Pole Mountain, near the city of Hot Springs in the state's southwestern corner. Firefighter killed, another injured as U.S. forests continue to burn August 12, 2000 Wildfires spur more Montana evacuations August 11, 2000 Army sending more troops to Western wildfire zone August 10, 2000 Now 70 large wildfires in West August 9, 2000 Exhausted firefighters return to battle after presidential praise August 8, 2000 More Army troops called to fight Western wildfires August 7, 2000 Wildfire smoke triggers health alert, may force new evacuations August 6, 2000 National Interagency Fire Center National Wildland/Urban Interface Fire Protection Program National Association of State Foresters U.S. Bureau of Land Management Firehouse.Com Idaho Large Wildland Fires Access Idaho - The Official Website of the State of Idaho State of Montana Fire Information U.S. Forest Service Note: Pages will open in a new browser window External sites are not endorsed by CNN Interactive. | X3: http://web.archive.org/web/20040901023251/http://www.cnn.com:80/2000/US/08/13/wildfires.02/index.html | Y3: found | Z3: 600 | AA3: cnn.com | AB3: -6.27 | AC3: -2.5 | AD3: Left-leaning
A4: 3 | B4: 2 | C4: Western Fire Season (Spring-Summer 2000) | D4: Wildfire | E4: 20000301 | F4: 20000831 | G4: 1978 | H4: 1075 | I4: 0 | J4: AK,AZ,CA,CO,HI,ID,MT,NM,NV,OR,UT,WA,WY | K4: 15,16,17,18,National | L4: http://www.cnn.com/2000/US/07/04/colorado.wildfires/index.html | M4: Two wildfires burn in Colorado - July 4, 2000 - CNN | N4: Jul 4, 2000 ... June 15, 2000. Wildfires rage in western United States June 14, 2000. Firefighters gain hold on Southern California wildfire. June 12, 2000 | O4: Relevant | P4: 0 | Q4: C | S4: FALSE | T4: The article directly covers two specific wildfires burning in Colorado in July 2000, which falls within the event window and affected states. It is pure event reporting — detailing acreage burned, locations, and firefighting conditions — with no discussion of climate change or any other causal framing. | U4: =IF(SUMPRODUCT(--ISNUMBER(SEARCH('National Domains'!$A$2:$A$48,L4)))>0,"Yes","No") | V4: =IF(COUNTIFS(Calibration!$A:$A,A4,Calibration!$B:$B,B4)>0,"Yes","No") | W4: CRAIG, Colorado (CNN) -- Firefighters were battling two wildfires Tuesday in remote areas of western Colorado. The fires have already consumed 11,500 acres of land and are expected to grow. Officials reported no injuries and said there were no structures immediately threatened by either blaze, both of which began Monday and are confined mostly to federal lands. The Buster Flats fire started in Dinosaur National Monument in the northwest corner of the state and moved into the nearby Diamond Breaks Wilderness Study Area and a small portion of the Brown's Park Wildlife Refuge, according to a press release from the Craig Interagency Dispatch Center. Approximately 9,000 acres have burned. To the south, the Cone Mountain fire scorched at least 2,500 acres of land some outside the city of Gateway. David Lehmann, a spokesman for the federal interagency fire center in Grand Junction, said conditions were ripe for the fire to spread. "They're about the worst we've seen," he said of the dry conditions. So far, the city of Gateway is not in any danger from the blaze, he said. Firefighters have been hampered in their efforts to contain the blazes by low humidity and high winds. Lehmann said gusts have reach 25 mph. Fire rages on nuclear reservation in Washington state June 29, 2000 One Colorado fire under control; another nearly contained June 20, 2000 Changing weather may aid crews battling Colorado wildfires June 15, 2000 Wildfires rage in western United StatesJune 14, 2000 Firefighters gain hold on Southern California wildfire June 12, 2000 Wildfires still burning in 4 U.S. states June 5, 2000 City of Craig Craig Colorado Police Department Colorado State Parks Dinosaur National Monument Cone Mountain Grand Junction Visitor and Convention Bureau Note: Pages will open in a new browser window External sites are not endorsed by CNN Interactive. | X4: https://web.archive.org/web/20260620001356/https://www.cnn.com/2000/US/07/04/colorado.wildfires/index.html | Y4: found | Z4: 302 | AA4: cnn.com | AB4: -6.27 | AC4: -2.5 | AD4: Left-leaning
A5: 3 | B5: 3 | C5: Western Fire Season (Spring-Summer 2000) | D5: Wildfire | E5: 20000301 | F5: 20000831 | G5: 1978 | H5: 1075 | I5: 0 | J5: AK,AZ,CA,CO,HI,ID,MT,NM,NV,OR,UT,WA,WY | K5: 15,16,17,18,National | L5: http://www.cnn.com/2000/US/09/12/wildfires.01/index.html | M5: West still on wildfire watch - September 12, 2000 - CNN | N5: Sep 12, 2000 ... The National Interagency Fire Center reported that several states, mostly in the West, have very high to extreme fire conditions -- Arizona, ... | O5: Borderline | S5: FALSE | T5: The article is dated September 12, 2000, just outside the event window (March–August 2000), and primarily reports on ongoing fire conditions as the season winds down, referencing the cumulative 2000 fire season acreage. It plausibly covers the tail end of the Western Fire Season event but is thin on specific event details and the date falls slightly outside the defined window. | U5: =IF(SUMPRODUCT(--ISNUMBER(SEARCH('National Domains'!$A$2:$A$48,L5)))>0,"Yes","No") | V5: =IF(COUNTIFS(Calibration!$A:$A,A5,Calibration!$B:$B,B5)>0,"Yes","No") | W5: By CNN.com Senior Writer Jim Morris BOISE, Idaho (CNN) -- Despite a dramatic drop in U.S. wildfire activity, firefighters said Tuesday their guard is still up. The National Interagency Fire Center reported that several states, mostly in the West, have very high to extreme fire conditions -- Arizona, Arkansas, California, Colorado, Idaho, Kansas, Montana, Nevada, Oklahoma, Oregon, Texas, Utah and Wyoming. On the positive side, the NIFC said rain helped firefighters contain the four remaining Texas wildfires, including the 15,864-acre (25-square-mile) Moore Branch blaze, 30 miles north of Beaumont. A week ago, there were 81 large wildfires in the United States, including 25 each in Texas and Montana. On Tuesday, the fire center reported 13 blazes in six states: • California (1 fire) • Florida (1) • Idaho (2) • Montana (7) • Nevada (1) • Wyoming (1) So far this year, wildfires throughout the United States have burned 6,649,279 acres (10,389 square miles), the fire center said Tuesday. By comparison, the land area of New Jersey is 7,418 square miles; Massachusetts is 7,838 square miles; New Hampshire is 8,969 square miles; Vermont is 9,249 square miles; and Maryland is 9,774 square miles. 'Good progress' against U.S. wildfiresSeptember 8, 2000 U.S. wildfires tamed, but not outSeptember 7, 2000 Texas takes lead in number of U.S. wildfiresSeptember 6, 2000 Wildland Fire Potential Assessment (through Oct 5) National Interagency Fire Center (NIFC) • Texas Wildland Fires 2000 Note: Pages will open in a new browser window External sites are not endorsed by CNN Interactive. | X5: http://web.archive.org/web/20040811191020/http://www.cnn.com:80/2000/US/09/12/wildfires.01/index.html | Y5: found | Z5: 252 | AA5: cnn.com | AB5: -6.27 | AC5: -2.5 | AD5: Left-leaning
A6: 3 | B6: 4 | C6: Western Fire Season (Spring-Summer 2000) | D6: Wildfire | E6: 20000301 | F6: 20000831 | G6: 1978 | H6: 1075 | I6: 0 | J6: AK,AZ,CA,CO,HI,ID,MT,NM,NV,OR,UT,WA,WY | K6: 15,16,17,18,National | L6: http://www.cnn.com/2000/NATURE/08/18/urban.interface/index.html | M6: Western wildfires often battled in the front yard - August 18, 2000 | N6: Aug 18, 2000 ... As the wildfires continue to burn in Montana's Bitteroot Valley, nearly a quarter of a million acres of the Bitteroot National Forest have ... | O6: Relevant | P6: -1 | Q6: D | R6: other_human_causes | S6: FALSE | T6: The article covers the 2000 Montana/Bitterroot Valley wildfires directly, falling within the event window and affected states. The causal framing centers entirely on the "urban interface" problem — human settlement patterns pushing homes into historically fire-prone forests — with the mayor explicitly noting these forests "have for centuries burned on a regular basis," attributing risk to land-use decisions and natural fire cycles, with no mention of climate change. | U6: =IF(SUMPRODUCT(--ISNUMBER(SEARCH('National Domains'!$A$2:$A$48,L6)))>0,"Yes","No") | V6: =IF(COUNTIFS(Calibration!$A:$A,A6,Calibration!$B:$B,B6)>0,"Yes","No") | W6: August 18, 2000 Web posted at: 3:50 PM EDT (1950 GMT) By From Rick Lockridge CNN Science Correspondent DARBY, Montana (CNN) -- As the wildfires continue to burn in Montana's Bitteroot Valley, nearly a quarter of a million acres of the Bitteroot National Forest have already burned and more than 50 homes have been destroyed. Nearly 2,000 firefighters are battling the blazes and more are on the way. Although these are forest fires, crews often find themselves working in people's front yards. In recent years, thousands of families have built homes just outside the national forest. Authorities call this meeting of residence and forest an "urban interface." "This urban interface does not deal with large communities, but it deals with a lot of homes that are scattered and that makes it even more difficult, " said Sonny Lasalle with the U.S. Forest Service. Helicopters have dropped thousands of buckets of water to keep flames away from homes and air tankers have made countless trips to coat structures with flame retardant. Twenty-man crews have been working around the clock digging fire lines and lighting backfires, to create a barrier between the blazes and the houses. "Most of the resources this past week have gone to the structure protection. We've lost some structures in the incident but we've saved quite a few more than we've lost," according to Bob Summerfield, a fire information officer with the U.S. Forest Service. "We've had engines and crews out putting the bulk of their effort into taking measures around homes, building fire lines, setting up sprinkler systems and foaming houses to protect those structures," Summerfield said. Hundreds of residents have been evacuated and special crews have moved in to try to protect the homes. But some houses nestled in the trees are impossible to protect. Firefighters say there are things people can do to make their homes more fire-resistant. "The main thing is to get some vegetation away from your house, use building materials that are less fire prone and then have a little bit of a lawn. I know we all don't like to mow grass but have a little bit of lawn or a rock garden -- something that won't burn," said Fire Information Officer Bobby Kitchens. As the flames approach their neighborhoods, some residents have resorted to hiring professional loggers to cut the trees around the homes. They've learned a lesson from the less fortunate. Darby Mayor Forest Hayes offered this insight: "Our forests are born in fire and they die in fire. Now we have homes that are back in areas that have for centuries have burned on a regular basis. This year we have a fire that's going to change the way people live in this valley. It's unfortunate, but that's the bottom line." New wildfire evacuations in West August 18, 2000 U.S. wildfires burned more than 5 million acres so far this year August 17, 2000 State of Montana declared disaster area as fires rage August 16, 2000 Wildfires ignite forest management debate August 16, 2000 Wildfires grow faster than supply of firefighters August 15, 2000 GORP - Bitterroot National Forest USDA Forest Service Note: Pages will open in a new browser window External sites are not endorsed by CNN Interactive. | X6: http://web.archive.org/web/20040822120555/http://www.cnn.com:80/2000/NATURE/08/18/urban.interface/index.html | Y6: found | Z6: 541 | AA6: cnn.com | AB6: -6.27 | AC6: -2.5 | AD6: Left-leaning
A7: 3 | B7: 5 | C7: Western Fire Season (Spring-Summer 2000) | D7: Wildfire | E7: 20000301 | F7: 20000831 | G7: 1978 | H7: 1075 | I7: 0 | J7: AK,AZ,CA,CO,HI,ID,MT,NM,NV,OR,UT,WA,WY | K7: 15,16,17,18,National | L7: http://www.cnn.com/2000/US/09/08/wildfires.02/index.html | M7: 'Good progress' against U.S. wildfires - September 8, 2000 - CNN | N7: Sep 8, 2000 ... By Jim Morris CNN.com Senior Writer. GALLERY. Click here for images of the ongoing fight against the wildfires. WEATHER FORECASTS. Idaho | O7: Borderline | S7: FALSE | T7: The article is dated September 8, 2000, which falls just outside the event window (ending August 31, 2000), and while it references the ongoing western wildfire season with cumulative acreage stats, it is primarily a brief operational update focusing on fire status in Texas and the northern Rockies rather than substantively covering the documented spring-summer 2000 western fire event. The geographic focus also skews toward Texas, which is not among the listed affected states for this event. | U7: =IF(SUMPRODUCT(--ISNUMBER(SEARCH('National Domains'!$A$2:$A$48,L7)))>0,"Yes","No") | V7: =IF(COUNTIFS(Calibration!$A:$A,A7,Calibration!$B:$B,B7)>0,"Yes","No") | W7: By Jim Morris CNN.com Senior Writer BOISE, Idaho (CNN) -- Aided by favorable weather, firefighters said Friday they continued to make gains against wildfires in the northern Rockies. Meantime, Texas, which earlier this week had nearly three dozen large wildfires, now has just 10. "Windy, cool and moist conditions are expected to further help firefighters in Idaho and western Montana make gains on the largest and longest-lasting fires in the country," the Idaho-based National Interagency Fire Center said on its Web site. "We're making slow, but good progress," said a NIFC official. The agency said it expected the recent streak of fire-stopping weather in the northern Rockies could continue over the weekend, although "winds could be a problem." To the south, "cooler temperatures, higher humidity, and precipitation will prevail in Louisiana, Arkansas, Mississippi and eastern Texas," the fire center said. But elsewhere in Texas and in Oklahoma weather is expected to be hot and dry. Nationally, there are 50 wildfires Friday, spread out in 11 states, according to the fire center. The states are: California (1 fire), Idaho (6), Mississippi (1), Montana (23), Nebraska (1), Nevada (1), Oklahoma (3), South Dakota (1), Texas (10), Utah (1) and Wyoming (2). The 10 wildfires reported in Texas on Friday represents a sharp drop from 35 in the state just two days earlier. So far this year, wildfires throughout the United States have burned 6,654,602 acres (10, 397 square miles), the fire center said Friday. By comparison, the land area of New Jersey is 7,418 square miles; Massachusetts is 7,838 square miles; New Hampshire is 8,969 square miles; Vermont is 9,249 square miles; and Maryland is 9,774 square miles. Texas takes lead in number of U.S. wildfires September 6, 2000 More wildfires erupt deep in the hot of Texas September 5, 2000 No Labor Day break for wildfire fighters September 4, 2000 Devils Tower National Monument in Wyoming closed as wildfire burns nearby September 3, 2000 Fires erupt in sizzling Texas as rain dampens West September 2, 2000 Texas State Forest Service Northern Rockies Coordination Center The Army National Guard National Interagency Fire Center Federal Emergency Management Agency • Federal Disaster Aid Ordered for Montana USDA Forest Service National Park Service Note: Pages will open in a new browser window External sites are not endorsed by CNN Interactive. | X7: https://web.archive.org/web/20260620001525/https://www.cnn.com/2000/US/09/08/wildfires.02/index.html | Y7: found | Z7: 385 | AA7: cnn.com | AB7: -6.27 | AC7: -2.5 | AD7: Left-leaning
A8: 5 | B8: 1 | C8: Western/Central/Southeast Drought/Heat Wave (Spring-Fall 2000) | D8: Drought | E8: 20000301 | F8: 20001130 | G8: 9344.8 | H8: 4997.2 | I8: 140 | J8: AK,AL,AZ,CA,CO,FL,GA,HI,IA,ID,IL,IN,KS,KY,MI,MN,MO,MS,MT,NC,ND,NE,NM,NV,OH,OK,OR,SC,SD,TN,TX,UT,VA,WA,WI,WV,WY | K8: 10,11,12,13,14,15,16,17,18,3,4,5,6,7,8,9,National | L8: https://www.baltimoresun.com/2000/03/14/drought-forecast-in-much-of-us-some-states-face-crisis-md-warned-to-expect-less-rain-than-usual/ | M8: Drought forecast in much of U.S.; Some states face crisis; Md ... | N8: Mar 14, 2000 ... These frequently produce heavy rains in the Northwest, drought in the Southeast and more tropical storms and hurricanes in the Atlantic Ocean. | O8: Relevant | P8: -1 | Q8: D | R8: natural_variability | S8: FALSE | T8: The article substantively covers the spring 2000 drought forecast across the exact states in the event metadata, falling within the event window. Forecasters explicitly attribute the deepening drought to La Niña conditions in the eastern tropical Pacific, framing it as a natural climate cycle, with no mention of anthropogenic climate change. | U8: =IF(SUMPRODUCT(--ISNUMBER(SEARCH('National Domains'!$A$2:$A$48,L8)))>0,"Yes","No") | V8: =IF(COUNTIFS(Calibration!$A:$A,A8,Calibration!$B:$B,B8)>0,"Yes","No") | W8: WASHINGTON — Broad swaths of the United States, from Arizona to Georgia and from Nebraska to Ohio, face worsening drought conditions this spring, with potentially costly consequences for agriculture, navigation, water supplies and tourism, federal officials said yesterday. In its first-ever spring drought forecast, the U.S. Commerce Department said federal agencies are mobilizing to provide drought assistance to the affected regions. Officials urged state and local authorities to take steps to prepare for the expected water shortages. “The news is not good,” said Commerce Secretary William M. Daley. “The drought of 1999 remains with us in the new century, and our data indicate drought conditions are probably going to get worse before they get better.” Maryland and Virginia, hit hard by drought last summer, are not included in the federal warning. But both states are expected to get less rain than usual this spring, continuing a pattern of scarce rains that began in July 1998. Maryland has had five months of above-average precipitation in the past 21 months. Long-term drought conditions persist in Garrett County. Other parts of the country face far worse prospects this spring. Two-thirds of the Texas winter wheat crop has been rated in poor condition or worse. Agriculture officials said it was too early to know whether grain prices would be affected by the drought, because well-timed rains could head off serious damage. Louisiana, Mississippi and Alabama recorded their driest February in 106 years of recordkeeping, with no relief in sight. Low water in the upper Great Lakes has forced shipping interests to lighten their freighters by loading less cargo. Wildfires have blackened 208,000 acres this year, nearly four times the acreage burned by this time last year. Federal fire crews are being assigned in expectation of more fires this spring. Some are already battling fires in Kentucky. Agriculture Secretary Dan Glickman said the Clinton administration’s National Drought Policy Commission will issue a report this spring urging stepped-up federal investment in drought preparedness, water conservation and drought-mitigation projects. He said Clinton will ask Congress for an additional $1 billion in the fiscal 2001 budget to make crop insurance more accessible and affordable to farmers. “We must have a drought policy that will provide farmers with the tools to withstand drought, not just survive it,” Glickman said. Droughts are a normal part of climate variation. They cause an average of $6 billion in agricultural losses each year in the United States, twice as much as floods. In some years, droughts cause extraordinary damage. The drought of 1988 — which affected many of the regions facing drought this year — was the most costly weather disaster in U.S. history, with $40 billion in losses. Forecasters blamed this year’s deepening drought on La Nina conditions in the eastern tropical Pacific Ocean, which have persisted since July 1998. Abnormally cold surface water temperatures during La Ninas cause shifts in global weather patterns. These frequently produce heavy rains in the Northwest, drought in the Southeast and more tropical storms and hurricanes in the Atlantic Ocean. Those tropical storms and hurricanes often provide the moisture needed to break droughts. Last year, it took heavy rains from hurricanes Dennis and Floyd, and thunderstorms accompanying a series of cold fronts, to end the drought in Central and Eastern Maryland. The state’s western counties received little relief. Low stream flows The storms provided no relief beyond the East Coast. Stream flows in most of the East are well below normal. Some are at record lows for this time of year, said Charles G. Groat, director of the U.S. Geological Survey. “We should be seeing ground water recharge taking place now, and we’re not seeing that, either,” he said. “Think of it as not having enough money to put in the bank. When the dry summer hits, we may not have enough in savings to get through without problems.” Improved data Weather forecasters did not predict last summer’s drought in the mid-Atlantic states. This year’s forecasts were made possible by improved data gathering and more powerful computers, said D. James Baker, administrator of the National Oceanographic and Atmospheric Administration. “The government can’t guarantee a drenching rain this spring, but we can now provide early warning so people can plan for heat waves and dryness,” Daley said. There will also be seasonal forecasts on flood, drought, hurricanes, heat and storms. There was one bit of good news among the drought warnings. “We see limited risk of flooding this spring,” Daley said. Dry times in Md. Sixteen of the past 21 months have seen below-average precipitation at BWI (months with above-average rainfall in bold). Date Normal Actual (inches) June ’98 3.67 3.23 July ’98 3.69 1.42 Aug. ’98 3.92 0.91 Sept. ’98 3.41 1.27 Oct. ’98 2.98 1.06 Nov. ’98 3.32 1.13 Dec. ’98 3.41 1.27 Jan. ’99 3.05 4.70 Feb. ’99 3.12 2.65 Mar. ’99 3.38 3.46 April ’99 3.09 2.27 May ’99 3.72 1.72 June ’99 3.67 2.04 July ’99 3.69 2.06 Aug. ’99 3.92 6.14 Sept. ’99 3.41 11 .50 Oct. ’99 2.98 2.48 Nov. ’99 3.32 1.95 Dec. ’99 3.41 2.96 Jan. ’00 3.05 3.64 Feb. ’00 3.23 2.01 Mar. ’00 3.38 0.37 Note: March 2000 rainfall through 3/12 SOURCE: National Weather Service | X8: https://web.archive.org/web/20260620001701/https://www.baltimoresun.com/2000/03/14/drought-forecast-in-much-of-us-some-states-face-crisis-md-warned-to-expect-less-rain-than-usual/ | Y8: found | Z8: 869 | AA8: baltimoresun.com | AB8: -3.79 | AC8: 0 | AD8: Left-leaning
A9: 8 | B9: 1 | C9: Tropical Storm Allison (June 2001) | D9: Tropical Cyclone | E9: 20010605 | F9: 20010617 | G9: 15084 | H9: 8522 | I9: 43 | J9: LA,TX | K9: 13,14,15,National | L9: https://www.chron.com/news/houston-texas/article/Tropical-Storm-Allison-takesHouston-Galveston-by-2046653.php | M9: Tropical Storm Allison takesHouston, Galveston by surprise - Chron | N9: Jun 5, 2001 ... The first named storm of the hurricane season, Tropical Storm Allison ... He is a proud native of South Africa, citizen of the United States and ... | O9: Relevant | P9: 0 | Q9: C | S9: FALSE | T9: The article is directly about Tropical Storm Allison making landfall along the Texas/Louisiana coast in June 2001, covering its impacts on Houston, Galveston, and surrounding areas. There is no discussion of climate change, global warming, or any other causal framing — it is purely event reporting on storm impacts and meteorological development. | U9: =IF(SUMPRODUCT(--ISNUMBER(SEARCH('National Domains'!$A$2:$A$48,L9)))>0,"Yes","No") | V9: =IF(COUNTIFS(Calibration!$A:$A,A9,Calibration!$B:$B,B9)>0,"Yes","No") | W9: The first named storm of the hurricane season, Tropical Storm Allison, snuck up on the upper Texas and Louisiana coasts today with a steady rain that flooded streets and bayous. The storm, not even a blip on forecasters' radar screens 12 hours before it was named, remained nearly stationary this evening about 60 miles southwest of Galveston. The storm's leisurely crawl produced sweeping bands of showers that slowly moved up the Gulf Freeway Tuesday night, thoroughly soaking Harris, Brazoria and Galveston counties. Advertisement Article continues below this ad Friendswood and Pearland were hit by the heaviest rain, where 11 inches fell in some places. Flooding is expected in or near Brookside Village in Pearland and areas along and north of Hwy. 6. Travel is not recommended. Roads are impassable and several cars were stranded in Southdown subdivision in Pearland. Clover Field Airport reported 7.9 inches of rain while Friendswood reported 8.35 inches today. Advertisement Article continues below this ad Feeder roads between Hobby Airport and Clear Lake were also reported flooded. A flash flood warning was issued for northern Brazoria County until 10:35 p.m. The slow-moving storm dumped enough rain to close most intersections in the area, including the Gulf Freeway and its access roads at the Bay Area Boulevard. The National Weather Service reported a tornado near Manvel, but further details were not immediately available. Advertisement Article continues below this ad As the rain moved north toward downtown Houston, emergency management officials feared there would be more road closures and flooded bayous. "It's moving so slow that it's really hard to tell, but we're pretty concerned," said Frank Gutierrez, operations manager for the Harris County Office of Emergency Management. Baytown was also in the storm's path. Tides from the three bays that surround the east Harris County city were expected to swell to four or five feet -- two feet above normal -- with winds gusting up to 60 miles per hour. The sustained winds from the storm were not supposed to go over 35 miles-per-hour, however, said Bernard Olive, the city's emergency management director. Advertisement Article continues below this ad The storm's broad arc of showers extended all the way from below Galveston into coastal Alabama. Galveston was the first area to feel the storm's brunt early Tuesday afternoon, when winds gusted over 60 mph and rain slashed across the island for about 90 minutes. Waves crashed over the city's protective seawall, sloshing small portions of seaweed deposits that have plagued the beachfront in recent weeks onto Seawall Boulevard. Many streets in East End neighborhoods were under water but no building flooding was reported. Because of flooding on Highway 87 on the Bolivar Peninsula, the Galveston County Sheriff's Department asked Bolivar Ferry managers to cease service to the peninsula from Galveston. The ferry closed at about 2:30 p.m. and remained shut down less than an hour, when water on Highway 87 began to recede. Advertisement Article continues below this ad Shortly before 3 p.m., Galveston Mayor Roger "Bo" Quiroga recommended a voluntary evacuation of the low-lying 20-mile stretch of island west of the seawall. The recommendation remained in effect for about four hours as water in the area failed to reach dangerous levels. Damage was slight in Galveston. A large temporary signboard fell and damaged a fence at a motel on 61st Street but no injuries were reported. "The Gulf is angry right now," Quiroga said about 4 p.m. "The only thing I don't like is that it happened only four days into the hurricane season." As sunset approached, gusty winds and periodic blowing rain continued in south Galveston County as the last of Allison's storm clouds moved in from the gulf. Advertisement Article continues below this ad Kemah Waterfront also faced waves crashing against its bulkheads, and restaurants along the Clear Creek Channel were closed. "The problem is not from the rain but from waves on the bay side crashing over the bulkhead," said Kemah Police Chief Tommie Buchanan. The restaurants, which were hit hard by Tropical Storm Frances in 1998, were not flooded Tuesday. When most Houstonians awoke Tuesday, Allison was officially an upper level low pressure system centered 150 miles offshore in the northwestern Gulf of Mexico, and wasn't given much chance of strengthening. But by 2 p.m. an air force reserve "Hurricane Hunter" aircraft had flown into the weather system and discovered a full-blown tropical storm. Advertisement Article continues below this ad "It went right from nothing to a tropical storm," said Charles Roeseler, a forecaster at the National Weather Service's Alvin office. "We had convection persisting out in the Gulf yesterday (Monday), but last night was the first sign of any organization." Roeseler said forecasters initially thought they were dealing with a "hybrid" weather system, a cross between a tropical system and an extra-tropical system. They believed two essential ingredients for concocting a tropical system -- light high-altitude winds and a warm sea surface -- were missing from the stew. But when the aircraft flew through the system, the core temperatures were warmer than expected, and the winds increased significantly during the day. The storm developed so rapidly, Roeseler said, there was hardly any time to react. Advertisement Article continues below this ad "I don't think we are going to have time to worry," the forecaster said Tuesday afternoon as Allison began pushing ashore. Chronicle reporters Kevin Moran, Cindy Horswell and Ruth Rendon contributed to this story. | X9: https://web.archive.org/web/20260620001907/https://www.chron.com/news/houston-texas/article/tropical-storm-allison-takeshouston-galveston-by-2046653.php | Y9: found | Z9: 904 | AA9: chron.com | AB9: -0.75 | AC9: 0 | AD9: Left-leaning
A10: 8 | B10: 2 | C10: Tropical Storm Allison (June 2001) | D10: Tropical Cyclone | E10: 20010605 | F10: 20010617 | G10: 15084 | H10: 8522 | I10: 43 | J10: LA,TX | K10: 13,14,15,National | L10: https://www.chron.com/life/article/Fresh-news-Tropical-Storm-Allison-dumps-on-city-2048790.php | M10: Fresh news: Tropical Storm Allison dumps on city - Chron | N10: Jun 14, 2001 ... Tropical Storm Allison broke Houston's heart, but not its spirit. ... None of the hurricanes hit the United States. ... June 14, 2001. Chron ... | O10: Relevant | P10: 0 | Q10: C | S10: FALSE | T10: The article is clearly about Tropical Storm Allison's impact on Houston, TX in June 2001, covering damages, flooding, and recovery efforts. There is no mention of climate change or any causal attribution beyond describing the storm's unusual behavior (quick formation, circling back) in purely meteorological terms. | U10: =IF(SUMPRODUCT(--ISNUMBER(SEARCH('National Domains'!$A$2:$A$48,L10)))>0,"Yes","No") | V10: =IF(COUNTIFS(Calibration!$A:$A,A10,Calibration!$B:$B,B10)>0,"Yes","No") | W10: Tropical Storm Allison broke Houston's heart, but not its spirit. It dumped roughly 3 feet of rain on the city, caused $1 billion in damage and at least 20 deaths. It was the worst flooding in Houston since 1994, when 17 people were killed, 22,000 were left homeless and $700 million worth of property was damaged. Why was this storm so bad? Advertisement Article continues below this ad Weather forecasters called the storm unusual because it formed quickly in the Gulf of Mexico, dumped a load of rain on the area and then circled back a few days later, unloading more rain on the already soaked ground. What areas were hardest hit? Allison skipped around the city. Generally, parts of downtown Houston, the Texas Medical Center and homes located near Houston's many bayous and low-lying areas suffered the most damage. Such areas as Katy, west Houston, Baytown and Galveston were largely spared the brunt of the damage. Advertisement Article continues below this ad What is the extent of damage to area schools? More than half of the Houston Independent School District's 300 schools reported flood damage and more than a dozen were still dealing with substantial water damage earlier this week. The worst damage was reported at Edison and Holland middle schools, and Pleasantville, R.P. Harris, Scarborough, J.R. Harris, Browning, Concord, Allen, Mitchell, Petersen, Kashmere Gardens and Plum Creek elementary schools. Some North Forest ISD schools were so badly flooded that summer school classes have been postponed until Monday. Advertisement Article continues below this ad Six Aldine ISD schools, including Aldine High School, Hall Education Center, Smith Academy and Conley, Mendel and Johnson elementary schools, were damaged by the flood. The University of Houston reported most of the 105 buildings on its main campus suffered flood damage. Institutions at the Texas Medical Center lost as many as 30,000 research animals. Where did all the waist-high water go? It has either receded back into the bayous or has been absorbed into drainage systems. In some cases, the city had to use pumps to force the water through the drainage system because it's not set up to handle the quantity received in a short period of time. Advertisement Article continues below this ad Does this mean we are going to have a severe hurricane season? Not necessarily. Government forecasters are predicting a "normal" hurricane season -- eight to 11 storms, five to seven of them hurricanes -- or a calmer season that the past three seasons. Last year there were 14 tropical storms, including eight hurricanes and three major hurricanes. None of the hurricanes hit the United States. What's the difference between a tropical storm and a hurricane? Advertisement Article continues below this ad Tropical storms form and receive names when their circulating winds reach 39 miles per hour. They become hurricanes when their winds reach 74 mph and major hurricanes when their winds reach 111 mph. What kind of help is needed? Volunteer Houston has heard from 100 agencies that need assistance. Agencies need help in moving families out of their flooded homes, collecting donated items and making general repairs to damaged shelters. Advertisement Article continues below this ad Call Volunteer Houston at 713-965-0031 to learn about what you can do to help. | X10: https://web.archive.org/web/20260620002006/https://www.chron.com/life/article/fresh-news-tropical-storm-allison-dumps-on-city-2048790.php | Y10: found | Z10: 542 | AA10: chron.com | AB10: -0.75 | AC10: 0 | AD10: Left-leaning
